Workbook

Sheet 무기공
C6: 무기공 | D6: 아케인2추 | E6: 아케인1추 | F6: 제네2추 | G6: 제네1추 | I6: 무기공 보정
A7: 1 | B7: 아델 | C7: =if('스카우터'!$D$8=true,if('스카우터'!$E$8="1추",G7,F7),if('스카우터'!$E$8="1추",E7,D7)) -> 875 | D7: 759 | E7: 799 | F7: 828 | G7: 875 | I7: =C7-$C$7 -> 0
A8: 2 | B8: 히어로 | C8: =if('스카우터'!$D$8=true,if('스카우터'!$E$8="1추",G8,F8),if('스카우터'!$E$8="1추",E8,D8)) -> 875 | D8: 759 | E8: 799 | F8: 828 | G8: 875 | I8: =C8-$C$7 -> 0
A9: 3 | B9: 카데나 | C9: =if('스카우터'!$D$8=true,if('스카우터'!$E$8="1추",G9,F9),if('스카우터'!$E$8="1추",E9,D9)) -> 832 | D9: 725 | E9: 762 | F9: 789 | G9: 832 | I9: =C9-$C$7 -> -43
A10: 4 | B10: 메르세데스 | C10: =if('스카우터'!$D$8=true,if('스카우터'!$E$8="1추",G10,F10),if('스카우터'!$E$8="1추",E10,D10)) -> 832 | D10: 725 | E10: 762 | F10: 789 | G10: 832 | I10: =C10-$C$7 -> -43
A11: 5 | B11: 아크 | C11: =if('스카우터'!$D$8=true,if('스카우터'!$E$8="1추",G11,F11),if('스카우터'!$E$8="1추",E11,D11)) -> 707 | D11: 624 | E11: 654 | F11: 673 | G11: 707 | I11: =C11-$C$7 -> -168
A12: 6 | B12: 카이저 | C12: =if('스카우터'!$D$8=true,if('스카우터'!$E$8="1추",G12,F12),if('스카우터'!$E$8="1추",E12,D12)) -> 875 | D12: 759 | E12: 799 | F12: 828 | G12: 875 | I12: =C12-$C$7 -> 0
A13: 7 | B13: 호영 | C13: =if('스카우터'!$D$8=true,if('스카우터'!$E$8="1추",G13,F13),if('스카우터'!$E$8="1추",E13,D13)) -> 832 | D13: 725 | E13: 762 | F13: 789 | G13: 832 | I13: =C13-$C$7 -> -43
A14: 8 | B14: 나이트로드 | C14: =if('스카우터'!$D$8=true,if('스카우터'!$E$8="1추",G14,F14),if('스카우터'!$E$8="1추",E14,D14)) -> 574 | D14: 492 | E14: 512 | F14: 551 | G14: 574 | I14: =C14-$C$7 -> -301
A15: 9 | B15: 엔젤릭버스터 | C15: =if('스카우터'!$D$8=true,if('스카우터'!$E$8="1추",G15,F15),if('스카우터'!$E$8="1추",E15,D15)) -> 707 | D15: 624 | E15: 654 | F15: 673 | G15: 707 | I15: =C15-$C$7 -> -168
A16: 10 | B16: 팬텀 | C16: =if('스카우터'!$D$8=true,if('스카우터'!$E$8="1추",G16,F16),if('스카우터'!$E$8="1추",E16,D16)) -> 848 | D16: 733 | E16: 770 | F16: 804 | G16: 848 | I16: =C16-$C$7 -> -27
A17: 11 | B17: 듀얼블레이드 | C17: =if('스카우터'!$D$8=true,if('스카우터'!$E$8="1추",G17,F17),if('스카우터'!$E$8="1추",E17,D17)) -> 832 | D17: =725 -> 725 | E17: 762 | F17: 789 | G17: 832 | I17: =C17-$C$7 -> -43
A18: 12 | B18: 팔라딘 | C18: =if('스카우터'!$D$8=true,if('스카우터'!$E$8="1추",G18,F18),if('스카우터'!$E$8="1추",E18,D18)) -> 875 | D18: 759 | E18: 799 | F18: 828 | G18: 875 | I18: =C18-$C$7 -> 0
A19: 13 | B19: 제로 | C19: =if('스카우터'!$D$8=true,if('스카우터'!$E$8="1추",G19,F19),if('스카우터'!$E$8="1추",E19,D19)) -> 820 | D19: 714 | E19: 750 | F19: 779 | G19: 820 | I19: =C19-$C$7 -> -55
A20: 14 | B20: 메카닉 | C20: =if('스카우터'!$D$8=true,if('스카우터'!$E$8="1추",G20,F20),if('스카우터'!$E$8="1추",E20,D20)) -> 696 | D20: 615 | E20: 644 | F20: 662 | G20: 696 | I20: =C20-$C$7 -> -179
A21: 15 | B21: 아크메이지(불,독) | C21: =if('스카우터'!$D$8=true,if('스카우터'!$E$8="1추",G21,F21),if('스카우터'!$E$8="1추",E21,D21)) -> 1004 | D21: 865 | E21: 913 | F21: 949 | G21: 1004 | I21: =C21-$C$7 -> 129
A22: 16 | B22: 섀도어 | C22: =if('스카우터'!$D$8=true,if('스카우터'!$E$8="1추",G22,F22),if('스카우터'!$E$8="1추",E22,D22)) -> 832 | D22: 725 | E22: 762 | F22: 789 | G22: 832 | I22: =C22-$C$7 -> -43
A23: 17 | B23: 에반 | C23: =if('스카우터'!$D$8=true,if('스카우터'!$E$8="1추",G23,F23),if('스카우터'!$E$8="1추",E23,D23)) -> 1004 | D23: 865 | E23: 913 | F23: 949 | G23: 1004 | I23: =C23-$C$7 -> 129
A24: 18 | B24: 패스파인더 | C24: =if('스카우터'!$D$8=true,if('스카우터'!$E$8="1추",G24,F24),if('스카우터'!$E$8="1추",E24,D24)) -> 832 | D24: 725 | E24: 762 | F24: 789 | G24: 832 | I24: =C24-$C$7 -> -43
A25: 19 | B25: 은월 | C25: =if('스카우터'!$D$8=true,if('스카우터'!$E$8="1추",G25,F25),if('스카우터'!$E$8="1추",E25,D25)) -> 707 | D25: 624 | E25: 654 | F25: 673 | G25: 707 | I25: =C25-$C$7 -> -168
A26: 20 | B26: 아란 | C26: =if('스카우터'!$D$8=true,if('스카우터'!$E$8="1추",G26,F26),if('스카우터'!$E$8="1추",E26,D26)) -> 804 | D26: 703 | E26: 739 | F26: 763 | G26: 804 | I26: =C26-$C$7 -> -71
A27: 21 | B27: 루미너스 | C27: =if('스카우터'!$D$8=true,if('스카우터'!$E$8="1추",G27,F27),if('스카우터'!$E$8="1추",E27,D27)) -> 992 | D27: 853 | E27: 900 | F27: 938 | G27: 992 | I27: =C27-$C$7 -> 117
A28: 22 | B28: 다크나이트 | C28: =if('스카우터'!$D$8=true,if('스카우터'!$E$8="1추",G28,F28),if('스카우터'!$E$8="1추",E28,D28)) -> 875 | D28: 759 | E28: 799 | F28: 828 | G28: 875 | I28: =C28-$C$7 -> 0
A29: 23 | B29: 신궁 | C29: =if('스카우터'!$D$8=true,if('스카우터'!$E$8="1추",G29,F29),if('스카우터'!$E$8="1추",E29,D29)) -> 848 | D29: 736 | E29: 775 | F29: 804 | G29: 848 | I29: =C29-$C$7 -> -27
... A49: 43 | B49: 라라 | C49: =if('스카우터'!$D$8=true,if('스카우터'!$E$8="1추",G49,F49),if('스카우터'!$E$8="1추",E49,D49)) -> 992 | D49: 853 | E49: 900 | F49: 938 | G49: 992 | I49: =C49-$C$7 -> 117

Sheet 직업패시브
B5: 패시브
B6: 순스탯 | C6: 스탯퍼 | D6: 부스탯 | E6: 직업공격력 | F6: 공퍼 | G6: 뎀지 | H6: 보공 | I6: 최종뎀 | J6: 방무 | K6: 크뎀 | L6: 무기상수 | M6: 숙련도 | P6: 스탯창 조건
A7: 아델 | B7: 60 | C7: 0 | D7: 0 | E7: =150+if('스카우터'!D8=true,51,44) -> 201 | F7: 10 | G7: 0 | H7: 10 | I7: 49.5 | J7: 20 | K7: 10 | L7: 1.3 | M7: 0.9 | O7: 아델 | P7: 레조스택x, 메용사용
A8: 히어로 | B8: 30 | C8: 0 | D8: 30 | E8: 80 | F8: 0 | G8: 0 | H8: 20 | I8: 202.5 | J8: 50 | K8: 20 | L8: 1.44 | M8: 0.9 | O8: 히어로 | P8: 메용, 10콤보, 인레이지O, 분노
A9: 카데나 | B9: 80 | C9: 0 | D9: 30 | E9: 70 | F9: 0 | G9: 0 | H9: 0 | I9: 0 | J9: 20 | K9: 25 | L9: 1.3 | M9: 0.9 | O9: 카데나 | P9: 메용 사용, 스택X
A10: 메르세데스 | B10: 30 | C10: 0 | D10: 30 | E10: 90 | F10: 30 | G10: 50 | H10: 20 | I10: 38 | J10: 25 | K10: 30 | L10: 1.3 | M10: 0.85 | O10: 메르세데스 | P10: 메용, 앤시언트 스피릿 사용, 스택X
A11: 아크 | B11: 60 | C11: 0 | D11: 0 | E11: =110+if('스카우터'!D8=true,45,33) -> 155 | F11: 0 | G11: 0 | H11: 30 | I11: 32 | J11: 30 | K11: 30 | L11: 1.7 | M11: 0.9 | O11: 아크 | P11: 레프폼, 메용 사용 스펠버프X, 로디드X
A12: 카이저 | B12: 50 | C12: 0 | D12: 0 | E12: 115 | F12: 30 | G12: 0 | H12: 0 | I12: 20 | J12: 40 | K12: 15 | L12: 1.34 | M12: 0.9 | O12: 카이저 | P12: 인간폼, 공격모드, 모프3 블레이즈 업 사용
A13: 호영 | B13: 60 | C13: 0 | D13: 0 | E13: =110++if('스카우터'!D10="패시브1렙",2,0) -> 110 | F13: 10 | G13: 10 | H13: 20 | I13: =if('스카우터'!D10="패시브1렙",52.63,51.25) -> 51.25 | J13: 27 | K13: =40+if('스카우터'!D10="패시브1렙",1,0) -> 40 | L13: 1.3 | M13: 0.9 | O13: 호영 | P13: 메용 사용
A14: 나이트로드 | B14: 50 | C14: 0 | D14: 30 | E14: 70 | F14: 0 | G14: 0 | H14: 10 | I14: 25 | J14: 30 | K14: 30 | L14: 1.75 | M14: 0.9 | O14: 나이트로드 | P14: 메용 사용
A15: 엔젤릭버스터 | B15: 80 | C15: 0 | D15: 0 | E15: 90 | F15: 0 | G15: 20 | H15: 0 | I15: 10 | J15: 15 | K15: 60 | L15: 1.7 | M15: 0.95 | O15: 엔젤릭버스터 | P15: 메용, 소울게이즈 사용 로디드X
A16: 팬텀 | B16: 140 | C16: 0 | D16: 40 | E16: 80 | F16: 0 | G16: 30 | H16: 0 | I16: 62.5 | J16: 30 | K16: 15 | L16: 1.3 | M16: 0.9 | O16: 팬텀 | P16: 메용 사용
A17: 듀얼블레이드 | B17: 30 | C17: 0 | D17: 30 | E17: 90 | F17: 0 | G17: 0 | H17: 0 | I17: 20 | J17: 0 | K17: 13 | L17: 1.3 | M17: 0.9 | O17: 듀얼블레이드 | P17: 메용 사용
A18: 팔라딘 | B18: 30 | C18: 0 | D18: 30 | E18: 30 | F18: 0 | G18: 0 | H18: 0 | I18: 71.82 | J18: 31 | K18: 20 | L18: 1.34 | M18: 0.9 | O18: 팔라딘 | P18: 메용, 컴뱃, 엘포, 가드 사용 0차지
A19: 제로 | B19: 50 | C19: 0 | D19: 0 | E19: 100 | F19: 0 | G19: 0 | H19: 90 | I19: 31.25 | J19: 28 | K19: 0 | L19: 1.49 | M19: 0.9 | O19: 제로 | P19: 제로-베타 디바인포스, 메용
A20: 메카닉 | B20: 30 | C20: 0 | D20: 30 | E20: =75+if('스카우터'!D10="패시브1렙",1,0) -> 75 | F20: 0 | G20: 10 | H20: 0 | I20: 20 | J20: 30 | K20: 5 | L20: 1.5 | M20: 0.85 | O20: 메카닉 | P20: 탱크상태, 메용 사용 로디드X
A21: 아크메이지(불,독) | B21: 40 | C21: 0 | D21: 0 | E21: 70 | F21: 0 | G21: 50 | H21: 0 | I21: 40 | J21: 20 | K21: 13 | L21: 1.2 | M21: 0.95 | O21: 아크메이지(불,독) | P21: 메용, 메디테이션 사용 오버로드 마나X
A22: 섀도어 | B22: 60 | C22: 0 | D22: 30 | E22: 160 | F22: 0 | G22: 0 | H22: 0 | I22: 25 | J22: 20 | K22: 45 | L22: 1.3 | M22: 0.9 | O22: 섀도어 | P22: 메용 사용, 플립 더 코인 0스택, 프리마 크리티컬 크뎀10퍼
A23: 에반 | B23: 50 | C23: 0 | D23: 10 | E23: 185 | F23: 35 | G23: 20 | H23: 20 | I23: 49.5 | J23: 20 | K23: 40 | L23: 1.2 | M23: 0.95 | O23: 에반 | P23: 메용, 오닉스의 축복, 교감 사용 오버로드 마나X
A24: 패스파인더 | B24: 110 | C24: 0 | D24: 30 | E24: 80 | F24: 20 | G24: 10 | H24: 0 | I24: 0 | J24: 30 | K24: 18 | L24: 1.3 | M24: 0.85 | O24: 패스파인더 | P24: 메용, 샤프 아이즈 사용
A25: 은월 | B25: 60 | C25: 0 | D25: 0 | E25: 20 | F25: 0 | G25: 20 | H25: 30 | I25: 26.5 | J25: 30 | K25: 20 | L25: 1.7 | M25: 0.9 | O25: 은월 | P25: 메용 사용, 로디드X
A26: 아란 | B26: 30 | C26: 0 | D26: 30 | E26: 180 | F26: 5 | G26: 20 | H26: 0 | I26: 0 | J26: 40 | K26: 18 | L26: 1.49 | M26: 0.9 | O26: 아란 | P26: 메용 사용, 500콤보
A27: 루미너스 | B27: 60 | C27: 0 | D27: 0 | E27: 80 | F27: 0 | G27: 15 | H27: 0 | I27: 82 | J27: 49 | K27: 15 | L27: 1.2 | M27: 0.95 | O27: 루미너스 | P27: 메용, 포틱 메디테이션 사용 오버로드 마나X
A28: 다크나이트 | B28: 30 | C28: 0 | D28: 30 | E28: 100 | F28: 0 | G28: 5 | H28: 0 | I28: 134 | J28: 37 | K28: 38 | L28: 1.49 | M28: 0.9 | O28: 다크나이트 | P28: 비홀더, 메용, 크오체사용
A29: 신궁 | B29: 70 | C29: 0 | D29: 30 | E29: 60 | F29: 0 | G29: 15 | H29: 0 | I29: 38 | J29: 25 | K29: 43 | L29: 1.35 | M29: 0.85 | O29: 신궁 | P29: 메용, 샤프아이즈, 아쳐리 사용
A30: 캐논슈터 | B30: 90 | C30: 0 | D30: 90 | E30: 60 | F30: 0 | G30: 0 | H30: 40 | I30: 43 | J30: 20 | K30: 5 | L30: 1.5 | M30: 0.85 | O30: 캐논슈터 | P30: 메용, 몽키 매직 사용 로디드X
A31: 캡틴 | B31: 30 | C31: 0 | D31: 30 | E31: 90 | F31: 20 | G31: 0 | H31: 0 | I31: 20 | J31: 20 | K31: 55 | L31: 1.5 | M31: 0.85 | O31: 캡틴 | P31: 메용, 파이렛 스타일 사용 로디드X
A32: 보우마스터 | B32: 120 | C32: 0 | D32: 30 | E32: 150 | F32: 25 | G32: 0 | H32: 0 | I32: 30 | J32: 25 | K32: 16 | L32: 1.3 | M32: 0.85 | O32: 보우마스터 | P32: 메용, 소울 애로우, 샤프아이즈 아쳐리 사용
... A37: 바이퍼 | B37: 30 | C37: 0 | D37: 30 | E37: 90 | F37: 30 | G37: 0 | H37: 20 | I37: 0 | J37: 0 | K37: 15 | L37: 1.7 | M37: 0.9 | O37: 바이퍼 | P37: 메용, 바이퍼지션 사용 미완충 상태, 로디드X
A38: 소울마스터 | B38: =110+'스카우터'!C8*0.5 -> 247.5 | C38: 0 | D38: 50 | E38: =215 -> 215 | F38: 10 | G38: 0 | H38: 15 | I38: 25 | J38: 37 | K38: 15 | L38: 1.34 | M38: 0.9 | O38: 소울마스터 | P38: 메용, 소울포지, 솔루나 타임 사용
A39: 플레임위자드 | B39: =60+0.5*'스카우터'!C8 -> 197.5 | C39: 0 | D39: 0 | E39: 95 | F39: 10 | G39: 0 | H39: 0 | I39: 95 | J39: 30 | K39: 20 | L39: 1.2 | M39: 0.95 | O39: 플레임위자드 | P39: 메용, 북 오브 파이어 사용 오버로드 마나X
A40: 윈드브레이커 | B40: =50+'스카우터'!C8*0.5 -> 187.5 | C40: 0.15 | D40: 30 | E40: 125 | F40: 20 | G40: 35 | H40: 40 | I40: 25 | J40: 15 | K40: 28 | L40: 1.3 | M40: 0.85 | O40: 윈드브레이커 | P40: 메용, 실프스 에이드, 샤프아이즈 엘리멘트 : 스톰 사용
A41: 나이트워커 | B41: =60+'스카우터'!C8*0.5 -> 197.5 | C41: 0 | D41: 0 | E41: 65 | F41: 10 | G41: 30 | H41: 0 | I41: 15 | J41: 15 | K41: 30 | L41: 1.75 | M41: 0.85 | O41: 나이트워커 | P41: 메용 사용
A42: 스트라이커 | B42: =60+'스카우터'!C8*0.5 -> 197.5 | C42: 0 | D42: 0 | E42: 55 | F42: 10 | G42: 5 | H42: 0 | I42: 20 | J42: 9 | K42: 45 | L42: 1.7 | M42: 0.9 | O42: 스트라이커 | P42: 메용 사용 로디드X
A43: 미하일 | B43: 90 | C43: 0 | D43: 30 | E43: 110 | F43: 10 | G43: 60 | H43: 0 | I43: 64.45 | J43: 40 | K43: 20 | L43: 1.2 | M43: 0.9 | O43: 미하일 | P43: 메용, 격려, 소울 레이지 사용 소울 링크X
A44: 배틀메이지 | B44: 40 | C44: 0 | D44: 0 | E44: 80 | F44: 40 | G44: 70 | H44: 0 | I44: 15 | J44: 30 | K44: 50 | L44: 1.2 | M44: 0.95 | O44: 배틀메이지 | P44: 메용, 다크 오라, 배틀레이지 사용 오버로드 마나X
A45: 와일드헌터 | B45: 130 | C45: 0 | D45: 70 | E45: 100 | F45: 35 | G45: 10 | H45: 10 | I45: 20 | J45: 30 | K45: 48 | L45: 1.35 | M45: 0.85 | O45: 와일드헌터 | P45: 메용, 소울 애로우, 샤프아이즈 하울링 서먼 재규어 사용
A46: 데몬슬레이어 | B46: 30 | C46: 0 | D46: 30 | E46: 100 | F46: 0 | G46: 35 | H46: 0 | I46: 25 | J46: 30 | K46: 15 | L46: 1.2 | M46: 0.9 | O46: 데몬슬레이어 | P46: 메용, 메타모포시스 사용
A47: 일리움 | B47: 40 | C47: 0 | D47: 0 | E47: =115+if('스카우터'!D8=true,71,52) -> 186 | F47: 10 | G47: 20 | H47: 30 | I47: 35 | J47: 25 | K47: 30 | L47: 1.2 | M47: 0.9 | O47: 일리움 | P47: 메용 사용 오버로드 마나X, 스택X
A48: 카인 | B48: 60 | C48: 0 | D48: 0 | E48: 110 | F48: 0 | G48: 10 | H48: 10 | I48: 87 | J48: 37 | K48: 40 | L48: 1.3 | M48: 0.85 | O48: 카인 | P48: 메용 사용
...

Sheet 보정패시브
E3: =1.495*1.65 -> 2.46675
B5: 패시브
B6: 순스탯 | C6: 스탯퍼 | D6: 부스탯 | E6: 직업공격력 | F6: 공퍼 | G6: 뎀지 | H6: 보공 | I6: 최종뎀 | J6: 방무 | K6: 크뎀 | L6: 무기상수 | M6: 숙련도
A7: 아델 | B7: ='직업패시브'!B7+'스카우터'!$E$14-10 -> 60 | C7: ='직업패시브'!C7 -> 0 | D7: ='직업패시브'!D7+'스카우터'!$E$15-10 -> 0 | E7: ='직업패시브'!E7+'무기공'!I7+'스카우터'!$E$16-3 -> 201 | F7: ='직업패시브'!F7 -> 10 | G7: ='직업패시브'!G7 -> 0 | H7: ='직업패시브'!H7 -> 10 | I7: =((1+'직업패시브'!I7/100)*if('스카우터'!$B$8="본섭",1,if('스카우터'!$C$8<250,(1+'보정상수'!$F$3),(1+'보정상수'!$F$4)))-1)*100 -> 49.5 | J7: ='직업패시브'!J7 -> 20 | K7: ='직업패시브'!K7 -> 10 | L7: ='직업패시브'!L7 -> 1.3 | M7: ='직업패시브'!M7 -> 0.9
A8: 히어로 | B8: ='직업패시브'!B8+'스카우터'!$E$14-10 -> 30 | C8: ='직업패시브'!C8 -> 0 | D8: ='직업패시브'!D8+'스카우터'!$E$15-10 -> 30 | E8: ='직업패시브'!E8+'무기공'!I8+'스카우터'!$E$16-3 -> 80 | F8: ='직업패시브'!F8 -> 0 | G8: ='직업패시브'!G8 -> 0 | H8: ='직업패시브'!H8 -> 20 | I8: =((1+'직업패시브'!I8/100)*if('스카우터'!$B$8="본섭",1,if('스카우터'!$C$8<250,(1+'보정상수'!$F$3),(1+'보정상수'!$F$4)))-1)*100 -> 202.5 | J8: ='직업패시브'!J8 -> 50 | K8: ='직업패시브'!K8 -> 20 | L8: ='직업패시브'!L8 -> 1.44 | M8: ='직업패시브'!M8 -> 0.9
A9: 카데나 | B9: ='직업패시브'!B9+'스카우터'!$E$14-10 -> 80 | C9: ='직업패시브'!C9 -> 0 | D9: ='직업패시브'!D9+'스카우터'!$E$15-10 -> 30 | E9: ='직업패시브'!E9+'무기공'!I9+'스카우터'!$E$16-3 -> 27 | F9: ='직업패시브'!F9 -> 0 | G9: ='직업패시브'!G9 -> 0 | H9: ='직업패시브'!H9 -> 0 | I9: =((1+'직업패시브'!I9/100)*if('스카우터'!$B$8="본섭",1,if('스카우터'!$C$8<250,(1+'보정상수'!$F$3),(1+'보정상수'!$F$4)))-1)*100 -> 0 | J9: ='직업패시브'!J9 -> 20 | K9: ='직업패시브'!K9 -> 25 | L9: ='직업패시브'!L9 -> 1.3 | M9: ='직업패시브'!M9 -> 0.9
A10: 메르세데스 | B10: ='직업패시브'!B10+'스카우터'!$E$14-10 -> 30 | C10: ='직업패시브'!C10 -> 0 | D10: ='직업패시브'!D10+'스카우터'!$E$15-10 -> 30 | E10: ='직업패시브'!E10+'무기공'!I10+'스카우터'!$E$16-3 -> 47 | F10: ='직업패시브'!F10 -> 30 | G10: ='직업패시브'!G10 -> 50 | H10: ='직업패시브'!H10 -> 20 | I10: =((1+'직업패시브'!I10/100)*if('스카우터'!$B$8="본섭",1,if('스카우터'!$C$8<250,(1+'보정상수'!$F$3),(1+'보정상수'!$F$4)))-1)*100 -> 38 | J10: ='직업패시브'!J10 -> 25 | K10: ='직업패시브'!K10 -> 30 | L10: ='직업패시브'!L10 -> 1.3 | M10: ='직업패시브'!M10 -> 0.85
A11: 아크 | B11: ='직업패시브'!B11+'스카우터'!$E$14-10 -> 60 | C11: ='직업패시브'!C11 -> 0 | D11: ='직업패시브'!D11+'스카우터'!$E$15-10 -> 0 | E11: ='직업패시브'!E11+'무기공'!I11+'스카우터'!$E$16-3 -> -13 | F11: ='직업패시브'!F11 -> 0 | G11: ='직업패시브'!G11 -> 0 | H11: ='직업패시브'!H11 -> 30 | I11: =((1+'직업패시브'!I11/100)*if('스카우터'!$B$8="본섭",1,if('스카우터'!$C$8<250,(1+'보정상수'!$F$3),(1+'보정상수'!$F$4)))-1)*100 -> 32 | J11: ='직업패시브'!J11 -> 30 | K11: ='직업패시브'!K11 -> 30 | L11: ='직업패시브'!L11 -> 1.7 | M11: ='직업패시브'!M11 -> 0.9
A12: 카이저 | B12: ='직업패시브'!B12+'스카우터'!$E$14-10 -> 50 | C12: ='직업패시브'!C12 -> 0 | D12: ='직업패시브'!D12+'스카우터'!$E$15-10 -> 0 | E12: ='직업패시브'!E12+'무기공'!I12+'스카우터'!$E$16-3 -> 115 | F12: ='직업패시브'!F12 -> 30 | G12: ='직업패시브'!G12 -> 0 | H12: ='직업패시브'!H12 -> 0 | I12: =((1+'직업패시브'!I12/100)*if('스카우터'!$B$8="본섭",1,if('스카우터'!$C$8<250,(1+'보정상수'!$F$3),(1+'보정상수'!$F$4)))-1)*100 -> 20 | J12: ='직업패시브'!J12 -> 40 | K12: ='직업패시브'!K12 -> 15 | L12: ='직업패시브'!L12 -> 1.34 | M12: ='직업패시브'!M12 -> 0.9
A13: 호영 | B13: ='직업패시브'!B13+'스카우터'!$E$14-10 -> 60 | C13: ='직업패시브'!C13 -> 0 | D13: ='직업패시브'!D13+'스카우터'!$E$15-10 -> 0 | E13: ='직업패시브'!E13+'무기공'!I13+'스카우터'!$E$16-3 -> 67 | F13: ='직업패시브'!F13 -> 10 | G13: ='직업패시브'!G13 -> 10 | H13: ='직업패시브'!H13 -> 20 | I13: =((1+'직업패시브'!I13/100)*if('스카우터'!$B$8="본섭",1,if('스카우터'!$C$8<250,(1+'보정상수'!$F$3),(1+'보정상수'!$F$4)))-1)*100 -> 51.25 | J13: ='직업패시브'!J13 -> 27 | K13: ='직업패시브'!K13 -> 40 | L13: ='직업패시브'!L13 -> 1.3 | M13: ='직업패시브'!M13 -> 0.9
A14: 나이트로드 | B14: ='직업패시브'!B14+'스카우터'!$E$14-10 -> 50 | C14: ='직업패시브'!C14 -> 0 | D14: ='직업패시브'!D14+'스카우터'!$E$15-10 -> 30 | E14: ='직업패시브'!E14+'무기공'!I14+'스카우터'!$E$16-3 -> -231 | F14: ='직업패시브'!F14 -> 0 | G14: ='직업패시브'!G14 -> 0 | H14: ='직업패시브'!H14 -> 10 | I14: =((1+'직업패시브'!I14/100)*if('스카우터'!$B$8="본섭",1,if('스카우터'!$C$8<250,(1+'보정상수'!$F$3),(1+'보정상수'!$F$4)))-1)*100 -> 25 | J14: ='직업패시브'!J14 -> 30 | K14: ='직업패시브'!K14 -> 30 | L14: ='직업패시브'!L14 -> 1.75 | M14: ='직업패시브'!M14 -> 0.9
A15: 엔젤릭버스터 | B15: ='직업패시브'!B15+'스카우터'!$E$14-10 -> 80 | C15: ='직업패시브'!C15 -> 0 | D15: ='직업패시브'!D15+'스카우터'!$E$15-10 -> 0 | E15: ='직업패시브'!E15+'무기공'!I15+'스카우터'!$E$16-3 -> -78 | F15: ='직업패시브'!F15 -> 0 | G15: ='직업패시브'!G15 -> 20 | H15: ='직업패시브'!H15 -> 0 | I15: =((1+'직업패시브'!I15/100)*if('스카우터'!$B$8="본섭",1,if('스카우터'!$C$8<250,(1+'보정상수'!$F$3),(1+'보정상수'!$F$4)))-1)*100 -> 10 | J15: ='직업패시브'!J15 -> 15 | K15: ='직업패시브'!K15 -> 60 | L15: ='직업패시브'!L15 -> 1.7 | M15: ='직업패시브'!M15 -> 0.95
A16: 팬텀 | B16: ='직업패시브'!B16+'스카우터'!$E$14-10 -> 140 | C16: ='직업패시브'!C16 -> 0 | D16: ='직업패시브'!D16+'스카우터'!$E$15-10 -> 40 | E16: ='직업패시브'!E16+'무기공'!I16+'스카우터'!$E$16-3 -> 53 | F16: ='직업패시브'!F16 -> 0 | G16: ='직업패시브'!G16 -> 30 | H16: ='직업패시브'!H16 -> 0 | I16: =((1+'직업패시브'!I16/100)*if('스카우터'!$B$8="본섭",1,if('스카우터'!$C$8<250,(1+'보정상수'!$F$3),(1+'보정상수'!$F$4)))-1)*100 -> 62.5 | J16: ='직업패시브'!J16 -> 30 | K16: ='직업패시브'!K16 -> 15 | L16: ='직업패시브'!L16 -> 1.3 | M16: ='직업패시브'!M16 -> 0.9
A17: 듀얼블레이드 | B17: ='직업패시브'!B17+'스카우터'!$E$14-10 -> 30 | C17: ='직업패시브'!C17 -> 0 | D17: ='직업패시브'!D17+'스카우터'!$E$15-10 -> 30 | E17: ='직업패시브'!E17+'무기공'!I17+'스카우터'!$E$16-3 -> 47 | F17: ='직업패시브'!F17 -> 0 | G17: ='직업패시브'!G17 -> 0 | H17: ='직업패시브'!H17 -> 0 | I17: =((1+'직업패시브'!I17/100)*if('스카우터'!$B$8="본섭",1,if('스카우터'!$C$8<250,(1+'보정상수'!$F$3),(1+'보정상수'!$F$4)))-1)*100 -> 20 | J17: ='직업패시브'!J17 -> 0 | K17: ='직업패시브'!K17 -> 13 | L17: ='직업패시브'!L17 -> 1.3 | M17: ='직업패시브'!M17 -> 0.9
A18: 팔라딘 | B18: ='직업패시브'!B18+'스카우터'!$E$14-10 -> 30 | C18: ='직업패시브'!C18 -> 0 | D18: ='직업패시브'!D18+'스카우터'!$E$15-10 -> 30 | E18: ='직업패시브'!E18+'무기공'!I18+'스카우터'!$E$16-3 -> 30 | F18: ='직업패시브'!F18 -> 0 | G18: ='직업패시브'!G18 -> 0 | H18: ='직업패시브'!H18 -> 0 | I18: =((1+'직업패시브'!I18/100)*if('스카우터'!$B$8="본섭",1,if('스카우터'!$C$8<250,(1+'보정상수'!$F$3),(1+'보정상수'!$F$4)))-1)*100 -> 71.82 | J18: ='직업패시브'!J18 -> 31 | K18: ='직업패시브'!K18 -> 20 | L18: ='직업패시브'!L18 -> 1.34 | M18: ='직업패시브'!M18 -> 0.9
... A49: 라라 | B49: ='직업패시브'!B49+'스카우터'!$E$14-10 -> 40 | C49: ='직업패시브'!C49 -> 0 | D49: ='직업패시브'!D49+'스카우터'!$E$15-10 -> 0 | E49: ='직업패시브'!E49+'무기공'!I49+'스카우터'!$E$16-3 -> 252 | F49: ='직업패시브'!F49 -> 0 | G49: ='직업패시브'!G49 -> 25 | H49: ='직업패시브'!H49 -> 10 | I49: =((1+'직업패시브'!I49/100)*if('스카우터'!$B$8="본섭",1,if('스카우터'!$C$8<250,(1+'보정상수'!$F$3),(1+'보정상수'!$F$4)))-1)*100 -> 97.92 | J49: ='직업패시브'!J49 -> 40 | K49: ='직업패시브'!K49 -> 20 | L49: ='직업패시브'!L49 -> 1.2 | M49: ='직업패시브'!M49 -> 0.95
C50: ='직업패시브'!C50

Sheet 보정상수
B2: 쿨감 보정치 | E2: 리부트 보정치
B3: 노쿨감 | C3: 0 | E3: 200~249 | F3: 0.6
B4: 1초 | C4: 0.07 | E4: 250~299 | F4: 0.65
B5: 2초 | C5: 0.12 | E5: 300~ | F5: 0.7
B6: 3초 | C6: 0.19
B7: 4초 | C7: 0.24
B8: 5초 | C8: 0.31
B9: 6초 | C9: 0.36
B10: 7초 | C10: 0.43

Sheet 스카우터
B2: 직업 | G2: 어빌 보공 계산 변환(21.12.16 10:09), 쿨감 보정 수정(21.12.16 18:34)
B3: 아델
B4: 스탯창 조건
B5: ="시드링착용, 노도핑, "&vlookup(B3,'직업패시브'!O:P,2,0)&", 쓸만한 컴뱃 오더스X" -> 시드링착용, 노도핑, 레조스택x, 메용사용, 쓸만한 컴뱃 오더스X
B7: 서버 | C7: 레벨 | D7: 해방여부 | E7: 추옵
B8: 본섭 | C8: 275 | D8: TRUE | E8: 1추
B9: 메용 스탯(시드링 착용) | C9: 55784 | D9: 어빌리티
B10: 메용X 스탯(시드링 착용) | C10: 54277 | D10: 스펙미적용
B11: 부스탯 | C11: 8395 | D11: 쿨감
B12: 부스탯2(듀블,섀도어,카데나) | C12: 0 | D12: 4초
B13: 스공(뒷스공) | C13: 46760060 | D13: 보조무기 강화 | F13: 기존
B14: 데미지 | C14: 67 | D14: 주스탯 | E14: 10 | F14: 10
B15: 보스 데미지(+어빌 상추뎀) | C15: 398 | D15: 부스탯 | E15: 10 | F15: 10
B16: 방무 | C16: 89.03 | D16: 공격력/마력 | E16: 3 | F16: 3
B17: 쓸샾 후 크뎀 | C17: 82 | D17: 최종뎀
B18: 템 공격력/마력 퍼 | C18: 99 | D18: =vlookup(B3,'보정패시브'!A:I,9,0) -> 49.5
B19: 아케인심볼 스탯 | C19: 13200 | D19: 순스탯(메용x) | E19: ='계산'!F19 -> 5433
B20: 어센틱심볼 스탯 | C20: 1300 | D20: 스탯퍼 | E20: ='계산'!F12 -> 6.25
B21: 하이퍼스탯+어빌 스탯 | C21: 150 | D21: 공격력/마력 | E21: ='계산'!I13 -> 2978
B22: 유니온 공격대원 스탯 | C22: 240 | D22: 공마퍼 | E22: ='계산'!I10 -> 109
B23: 환산 주스탯
G24: 추가 스펙 시뮬레이터
B25: ='계산'!B41 -> 56554 | D25: =if(B25-$C$9>10000,"새틀라이트",if(B25-$C$9>4500,"지옥불",if(B25-$C$9>1500,"불",if(B25-$C$9>-1500 ,"적정",if(B25-$C$9>-4500,"물",if(B25-$C$9>-7500,"맹물","스탯딸")))))) -> 적정 | G25: 순스탯 | H25: 0 | I25: 예상
G26: 스탯퍼 | H26: 0
G27: 공격력/마력 | H27: 0 | I27: ='계산'!Q62 -> 56554 | K27: =if(I27-'계산'!O11>10000,"새틀라이트",if(I27-'계산'!O11>4500,"지옥불",if(I27-'계산'!O11>1500,"불",if(I27-'계산'!O11>-1500 ,"적정",if(I27-'계산'!O11>-4500,"물",if(I27-'계산'!O11>-7500,"맹물","스탯딸")))))) -> 적정
B28: =if(D25="새틀라이트","당신은 혹시 유니온 서버의 3만대 메카닉?",if(D25="지옥불","스탯 사기를 대체 얼마나 친거야?",if(D25="불","스탯 대비 강합니다. ??? : 이거 이 스탯 아님. 실제론 더쎔(팩트)",if(D25="적정","당신은 주스탯만큼 강하다. 어디 가서 몇만대라고 하고 다니세요.",if(D25="물","스탯 대비 약합니다. 스탯이 다가 아닙니다.",if(D25="맹물","스탯 대비 매우 약합니다. 약코 ㄴㄴ 님이 약한거에요.",if(D25="스탯딸","궁극의 스탯딸 검거. 어디가서 몇만대라고 말하고 다니지 마세여;;"))))))) -> 당신은 주스탯만큼 강하다. 어디 가서 몇만대라고 하고 다니세요. | G28: 보총뎀 | H28: 0
B29: 스탯창 주스탯 대비 | D29: ='계산'!F70 -> 0.0347 | G29: 공격력/마력 퍼 | H29: 0
G30: 크뎀 | H30: 0
B31: {=index('스카우터 기초자료'!B:B,match(B25,'스카우터 기초자료'!E:E,1))&" 대비"} -> 레전둘둘 대비 | D31: {=ROUND(('계산'!B39/index('스카우터 기초자료'!C:C,match(B25,'스카우터 기초자료'!E:E,1)))-1,4)} -> 0.0589 | G31: 방무 | H31: 0
G32: 스탯퍼 미포함 스탯 | H32: 0 | I32: =if(K27="새틀라이트","당신은 혹시 유니온 서버의 3만대 메카닉?",if(K27="지옥불","스탯 사기를 대체 얼마나 친거야?",if(K27="불","스탯 대비 강합니다. ??? : 이거 이 스탯 아님. 실제론 더쎔(팩트)",if(K27="적정","당신은 주스탯만큼 강하다. 어디 가서 몇만대라고 하고 다니세요.",if(K27="물","스탯 대비 약합니다. 스탯이 다가 아닙니다.",if(K27="맹물","스탯 대비 매우 약합니다. 약코 ㄴㄴ 님이 약한거에요.",if(K27="스탯딸","궁극의 스텟딸 검거. 어디가서 몇만대라고 말하고 다니지 마세여;;"))))))) -> 당신은 주스탯만큼 강하다. 어디 가서 몇만대라고 하고 다니세요.
B33: {=IF(B25<=80936, index('스카우터 기초자료'!B:B,match(B25,'스카우터 기초자료'!E:E,1)+1)&" 대비","그분들")} -> 노해방 초고스펙 대비 | D33: {=if(B25<=80936, ROUND(('계산'!B39/index('스카우터 기초자료'!C:C,match(B25,'스카우터 기초자료'!E:E,1)+1)-1),4),"")} -> -0.1956 | G33: 구버전 점수
G34: ='계산'!Q60 -> 54.79

Sheet 사용법

Sheet 기준스펙
B3: 기준스펙
B4: 공통 | C4: 유니온 8천, 농장(데미지, 보공 크뎀) 풀, 노마약
B5: 기준 | C5: 레벨 | D5: 주스탯 | E5: 템세팅 | F5: 방어구 세팅 | G5: 장신구 세팅 | H5: 무보엠 세팅 | I5: 아케인(어센틱) 포스
B6: 에픽둘둘 | C6: 245 | D6: 2.3만 | E6: 3카5앱, 9보장 | F6: 12성 9퍼 에디공10, 주흔작 | G6: 12성 9퍼 에디공10, 악공작 | H6: 무기앱솔 12성, 무릉기준 2줄 유효 에디공6 | I6: 890(0)
B7: 에픽+유닠(주요) | C7: 250 | D7: 2.6만 | E7: 1앜5앱2카, 9보장 | F7: 에픽둘둘세팅 + 장갑(17성, 크뎀+주탯) + 모자(30%or2초18%) | G7: 12성 9퍼 에디공10, 악공작 | H7: 무기아케인 17성, 보스기준 최적3줄 유효 에디공6 | I7: 1140(0)
B8: 유닠둘둘 | C8: 255 | D8: 3.57만 | E8: 1앜5앱2카, 9보장 | F8: 17성 15퍼 에디(주탯4 공10), 주흔작 | G8: 17성 15퍼 에디(주탯4 공10), 악공작 | H8: 무기아케인 17성, 보스기준 최적3줄 유효 에디공15 | I8: 1320(0)
B9: 18레전둘둘 | C9: 260 | D9: 4.54만 | E9: 1앜5앱2카, 9보장 | F9: 18성 27퍼 에디(주탯4 공10), 주흔작 | G9: 18성 27퍼 에디(주탯4 공10), 악공작 | H9: 무기아케인 17성, 보스기준 최적3줄 유효 에디공21 | I9: 1320(40)
B10: 레전둘둘 | C10: 270 | D10: 5.25만 | E10: 1앜5앱2카, 5보장 | F10: 22성 27퍼 에디(주탯5 공11), 주흔작 | G10: 22성 27퍼 에디(주탯5 공11), 프악공작 | H10: 무기아케인 17성, 보스기준 최적3줄 유효 에디공21 | I10: 1320(80)
B11: 노해방 초고스펙 | C11: 275 | D11: 6.28만 | E11: 1앜5앱2카, 5보장 | F11: 22성 30퍼 에디(주탯11퍼), 주흔작 | G11: 22성 30퍼 에디(주탯11퍼), 놀긍작, 놀12매커, 샤레마 + 가엔링 | H11: 무기아케인 17성, 무릉기준 최적3줄 유효 에디공21 | I11: 1320(110)
B12: 해방 초고스펙 | C12: 280 | D12: 6.67만 | E12: 4카5앱, 5보장 | F12: 22성 30퍼 에디(2줄+@), 주흔작 | G12: 22성 30퍼 에디(2줄+@), 놀긍작, 놀12매커, 샤레마, 스링 + 가엔링, | H12: 제네 해방, 무릉기준 최적3줄 유효 에디공21 | I12: 1320(130)
B13: 5칠흑 엔드 | C13: 280 | D13: 7.54만 | E13: 4카5앜, 5칠흑 | F13: 22성 30퍼 에디(2줄+@), 놀긍작 | G13: 5칠흑, 22성 30퍼 에디(2줄+@), 놀긍작, 놀12매커, 스링 + 가엔링, | H13: 제네 해방, 무릉기준 최적3줄 유효 보조 에디공30, 무기엠블 2+@ | I13: 1320(160)
B14: 엔드 | C14: 280 | D14: 8만 | E14: 4카5앜, 풀칠흑 | F14: 22성 33퍼 에디(3줄), 놀긍작 | G14: 풀칠흑, 22성 33퍼 에디(3줄), 놀긍작 | H14: 제네 해방, 무릉기준 최적3줄+한줄이탈, 에디공90 | I14: 1320(160)

Sheet 계산
B2: 직업 | C2: ='스카우터'!B3 -> 아델
B5: 기본정보 | E5: 스탯퍼 계산 | H5: 공격력/마력 계산 | K5: 순스탯 보정 | N5: 스탯 보정
B6: 레벨 | C6: ='스카우터'!C8 -> 275 | E6: 레벨 | F6: =C6 -> 275 | H6: 메용 스텟(시드링 착용) | I6: =C7 -> 55784 | K6: 순스탯 | L6: =F19 -> 5433 | N6: 보정 순스탯 | O6: =L8 -> 5433
B7: 메용 스텟(시드링 착용) | C7: ='스카우터'!C9 -> 55784 | E7: ap | F7: =18+F6*5 -> 1393 | H7: 부스탯 | I7: =C9 -> 8395 | K7: 추가 순스탯 | L7: ='스카우터'!H25 -> 0 | N7: 보정 스탯퍼 | O7: =L14 -> 6.25
B8: 메용X 스탯(시드링 착용) | C8: ='스카우터'!C10 -> 54277 | E8: 메용 스텟(시드링 착용) | F8: =C7 -> 55784 | H8: 스공(뒷스공) | I8: =C10 -> 46760060 | K8: 최종 순스탯 | L8: =L6+L7 -> 5433 | N8: ap | O8: =F7 -> 1393
B9: 부스탯 | C9: =I18 -> 8395 | E9: 메용X 스탯(시드링 착용) | F9: =C8 -> 54277 | H9: 데미지 | I9: =C11 -> 67 | N9: 스탯퍼 미포함 스탯 | O9: =F16+'스카우터'!H32 -> 14890
B10: 스공(뒷스공) | C10: ='스카우터'!C13 -> 46760060 | E10: 실메용증가량 | F10: =F8-F9 -> 1507 | H10: 공퍼 | I10: =C15+vlookup(C2,'직업패시브'!A:F,6,0) -> 109 | N10: 보정 메용X | O10: =ROUNDDOWN(O6*(1+O7),0)+O9 -> 54279
B11: 데미지 | C11: ='스카우터'!C14 -> 67 | E11: 순수메용증가량 | F11: =rounddown(F7*if('스카우터'!B3="팔라딘",0.16,0.15),0) -> 208 | H11: 최종뎀 | I11: ='스카우터'!D18 -> 49.5 | K11: 스탯퍼 보정 | N11: 보정 메용스탯 | O11: =O10+ROUND(ROUNDDOWN(O8*if('스카우터'!B3="팔라딘",0.16,0.15),0)*(1+O7),0) -> 55787
B12: 보스 데미지(+상추뎀) | C12: ='스카우터'!C15 -> 398 | E12: 스탯퍼 | F12: =ROUND((F10/F11-1)*100,0)/100 -> 6.25 | H12: 무기상수 | I12: =vlookup(C2,'직업패시브'!A:M,12,0) -> 1.3 | K12: 스탯퍼 | L12: =F12 -> 6.25
B13: 방무 | C13: ='스카우터'!C16 -> 89.03 | H13: 공격력/마력 | I13: =ROUNDUP(I8/((I6*4+I7)*0.01*I12*(1+I10/100)*(1+I9/100)*(1+I11/100)),) -> 2978 | K13: 추가 스탯퍼 | L13: ='스카우터'!H26 -> 0
B14: 쓸샾 후 크뎀 | C14: ='스카우터'!C17 -> 82 | E14: 순스탯 계산 | K14: 최종 스탯퍼 | L14: =L12+L13 -> 6.25
B15: 템공퍼 | C15: ='스카우터'!C18 -> 99 | E15: 메용X 스탯(시드링 착용) | F15: =C8 -> 54277 | H15: 부스탯 계산
B16: 아케인심볼 스탯 | C16: ='스카우터'!C19 -> 13200 | E16: 스탯퍼 미포함 스탯 | F16: =sum(C16:C19) -> 14890 | H16: 부스탯 | I16: ='스카우터'!C11 -> 8395
B17: 어센틱심볼 스탯 | C17: ='스카우터'!C20 -> 1300 | E17: 순수스탯량 | F17: =F15-F16 -> 39387 | H17: 부스탯2 | I17: ='스카우터'!C12 -> 0
B18: 하이퍼스탯+어빌 스탯 | C18: ='스카우터'!C21 -> 150 | E18: 스탯퍼 | F18: =F12 -> 6.25 | H18: 총 부스탯 | I18: =I16+IF(C2="듀얼블레이드",I17,IF(C2="섀도어",I17,IF(C2="카데나",I17,0))) -> 8395
B19: 유니온 공격대원 스탯 | C19: ='스카우터'!C22 -> 240 | E19: 순스탯 | F19: =ROUNDUP(F17/(1+F18),0) -> 5433
B23: 기본정보(0초 아델) | E23: 순스탯 보정 | H23: 공격력/마력 보정 | K23: 공/마퍼 보정 | N23: 방무 보정 | Q23: 샤드뎀계산
B24: 레벨 | C24: =C6 -> 275 | E24: 순스탯 | F24: =F19 -> 5433 | H24: 공격력/마력 | I24: =I13 -> 2978 | K24: 템 공격력/마력 | L24: =C15 -> 99 | N24: 방무 | O24: =C13 -> 89.03 | Q24: 주스탯 | R24: =F41+ROUNDDOWN(30*(1+F33),0) -> 57365
B25: 메용 스텟(시드링 착용) | C25: =F41 -> 57141 | E25: 현직업 보정패시브 순스탯 | F25: =vlookup(C2,'보정패시브'!A:B,2,0) -> 60 | H25: 현직업 보정패시브 공격력 | I25: =vlookup(C2,'보정패시브'!A:E,5,0) -> 201 | K25: 아델 공퍼 | L25: ='직업패시브'!F7 -> 10 | N25: 현직업 보정패시브 방무 | O25: =VLOOKUP(C2,'보정패시브'!A:J,10,0) -> 20 | Q25: 부스탯 | R25: =L40+ROUNDDOWN(30*L39,0) -> 8470
B26: 메용X 스탯(시드링 착용) | C26: =F40 -> 55583 | E26: 아델 패시브 순스탯 | F26: ='직업패시브'!B7 -> 60 | H26: 아델 패시브 공격력 | I26: ='직업패시브'!E7 -> 201 | K26: 보정 공퍼 | L26: =L24+L25 -> 109 | N26: 방무 역산 | O26: =(O24-O25)/(1-O25/100) -> 86.2875 | Q26: 스탯상수 | R26: =(R24*4+R25)/100 -> 2379.3
B27: 부스탯 | C27: =L40 -> 8395 | E27: 보정 순스탯 | F27: =F24-F25+F26 -> 5433 | H27: 보정 공격력 | I27: =I24-I25+I26 -> 2978 | N27: 아델 패시브 방무 | O27: ='직업패시브'!J7 -> 20 | Q27: 도핑 공격력 | R27: =I27+180 -> 3158
B28: 스공(뒷스공) | C28: =ROUNDDOWN((C25*4+C27)*O32*0.01*(1+C29/100)*(1+L26/100)*I27*(1+C34/100),0) -> 47867991 | N28: 보정 방무 | O28: =O26+(100-O26)*O27/100 -> 89.03 | Q28: 공퍼 상수 | R28: =1+(L26+4)/100 -> 2.13
B29: 데미지 | C29: =I33 -> 67 | E29: 스탯퍼 보정 | H29: 데미지 보정 | K29: 크뎀 보정 | N29: 샤드 방무 | O29: =O28+(100-O28)*20/100 -> 91.224 | Q29: 보총뎀 상수 | R29: =1+(I33+I40+6+90)/100 -> 6.61
B30: 보스 데미지(+상추뎀) | C30: =I40 -> 398 | E30: 스탯퍼 | F30: =F12 -> 6.25 | H30: 데미지 | I30: =C11 -> 67 | K30: 크뎀 | L30: =C14 -> 82 | Q30: 최종뎀 상수 | R30: =1+(C34)/100 -> 1.495
B31: 방무 | C31: =O28 -> 89.03 | E31: 쿨감 | F31: ='스카우터'!D12 -> 4초 | H31: 현직업 보정패시브 데미지 | I31: =vlookup(C2,'보정패시브'!A:G,7,0) -> 0 | K31: 현직업 보정패시브 크뎀 | L31: =vlookup(C2,'보정패시브'!A:K,11,0) -> 10 | N31: 직업 상수 | Q31: 방무상수 | R31: =(100-(C35-C35*O29/100))/100 -> 0.95612
B32: 쓸샾 후 크뎀 | C32: =L33 -> 82 | E32: 보정치 | F32: =vlookup(F31,'보정상수'!B:C,2,0) -> 0.24 | H32: 아델 패시브 데미지 | I32: ='직업패시브'!G7 -> 0 | K32: 아델 패시브 크뎀 | L32: ='직업패시브'!K7 -> 10 | N32: 무기상수 | O32: 1.3 | Q32: 크뎀상수 | R32: =(135+L33+30)/100 -> 2.47
B33: 템공퍼 | C33: =L24 -> 99 | E33: 보정 스탯퍼 | F33: =F30+F32 -> 6.49 | H33: 보정 데미지 | I33: =I30-I31+I32 -> 67 | K33: 보정 순스탯 | L33: =L30-L31+L32 -> 82 | N33: 숙련도 | O33: 0.9 | Q33: 렙차보정 | R33: 1.2
B34: 최종데미지 | C34: ='보정패시브'!I7 -> 49.5 | N34: 코강 | O34: 2.2 | Q34: 샤드퍼뎀 | R34: =O35 -> 4.5
B35: 몹 방어율 | C35: 50 | E35: 스탯 보정 | H35: 보공 보정 | K35: 부스탯 보정 | N35: 샤드데미지 | O35: 4.5 | Q35: 무기상수 | R35: =O32 -> 1.3
B36: 샤드데미지 | E36: 보정 순스탯 | F36: =F27 -> 5433 | H36: 보공 | I36: =C12 -> 398 | K36: 부스탯 | L36: =I16 -> 8395 | Q36: 숙련도 | R36: =(O33+1)/2 -> 0.95
B37: =Q38 -> 547994677 | E37: 보정 스탯퍼 | F37: =F33 -> 6.49 | H37: 현직업 보정패시브 보공 | I37: =vlookup(C2,'보정패시브'!A:H,8,0) -> 10 | K37: 현직업 보정패시브 부스탯 | L37: =vlookup(C2,'보정패시브'!A:D,4,0) -> 0 | Q37: 최종샤드뎀
B38: =TEXT(B37,"[>=100000000]#억####만####;[>=10000]#만####;#") -> 5억4799만4677 | E38: ap | F38: =F7 -> 1393 | H38: 아델 패시브 보공 | I38: ='직업패시브'!H7 -> 10 | K38: 아델 패시브 순스탯 | L38: ='직업패시브'!D7 -> 0 | Q38: =ROUNDDOWN(R26*R27*R28*R29*R30*R31*R32*R33*R34*R35*R36*2.2/10,0) -> 547994677
B39: =rounddown(B37/10000000,2) -> 54.79 | E39: 스탯퍼 미포함 스탯 | F39: =F16 -> 14890 | H39: 어빌 보공 | I39: =IF('스카우터'!D10="보공",10,0) -> 0 | K39: 부스탯 보정상수 | L39: 2.5
B40: =rounddown(log(B39/4.96)*100,2) -> 104.32 | E40: 보정 메용X | F40: =ROUNDDOWN(F36*(1+F37),0)+F39 -> 55583 | H40: 보정 보공 | I40: =I36-I37+I38-I39 -> 398 | K40: 보정 부스탯 | L40: =L36+(L38-L37)*L39 -> 8395
B41: =if(B40>0, round(1.7495*B40*B40+158.59*B40+20971,0),"출력불가능") -> 56554 | E41: 보정 메용스탯 | F41: =F40+ROUND(ROUNDDOWN(F38*0.15,0)*(1+F37),0) -> 57141
B44: 기본정보(4초 아델) | E44: 추가 순스탯 | H44: 공격력/마력 보정 | K44: 공/마퍼 보정 | N44: 방무 보정 | Q44: 샤드뎀계산
B45: 레벨 | C45: =C24 -> 275 | E45: 순스탯 | F45: =F27 -> 5433 | H45: 공격력/마력 | I45: =I27 -> 2978 | K45: 템 공격력/마력 | L45: =L26 -> 109 | N45: 방무 | O45: =O29 -> 91.224 | Q45: 주스탯 | R45: =F60+ROUNDDOWN(30*(1+F52),0) -> 57365
B46: 메용 스텟(시드링 착용) | C46: =F60 -> 57141 | E46: 추가 순스탯 | F46: ='스카우터'!H25 -> 0 | H46: 추가 공마 | I46: ='스카우터'!H27 -> 0 | K46: 추가 공퍼 | L46: ='스카우터'!H29 -> 0 | N46: 추가 방무 | O46: ='스카우터'!H31 -> 0 | Q46: 부스탯 | R46: =L40+ROUNDDOWN(30*L39,0) -> 8470
B47: 메용X 스탯(시드링 착용) | C47: =F59 -> 55583 | E47: 최종 순스탯 | F47: =F45+F46 -> 5433 | H47: 최종 공격력 | I47: =I45+I46 -> 2978 | K47: 최종 공퍼 | L47: =L45+L46 -> 109 | N47: 최종 방무 | O47: =O45+(100-O45)*O46/100 -> 91.224 | Q47: 스탯상수 | R47: =(R45*4+R46)/100 -> 2379.3
B48: 부스탯 | C48: =L40 -> 8395 | Q48: 도핑 공격력 | R48: =I47+180 -> 3158
...

Sheet 스카우터 기초자료
C4: 샤드뎀 | D4: 스카우터 | E4: 주스탯환산 | K4: 그래프 표현 | P4: 샤드뎀 | Q4: 스카우터 | R4: 기준스펙 스탯 | S4: 계산스탯 | T4: 2차계산 | V4: 스카우터 | W4: 주스탯
A5: 1 | B5: 에픽둘둘 | C5: 6.26 | D5: =rounddown(log(C5/4.96)*100,2) -> 10.1 | E5: =1.7495*D5*D5+158.59*D5+20971 -> 22751.226 | F5: =E5-20000 -> 2751.2255 | G5: =F5/$J$5 -> 5.1585478 | J5: =80000/150 -> 533.33333 | L5: 최대 | N5: 1 | O5: 에픽둘둘 | P5: 6.06 | Q5: =rounddown(log(P5/4.96)*100,2) -> 8.69 | R5: 23825 | S5: 22481.263 | T5: =1.7253*power(Q5,2)+162.82*Q5+20864 -> 22409.194 | V5: 8.69 | W5: 23825 | X5: 23825
A6: 2 | B6: 에픽+유닠(중요) | C6: 11.04 | D6: =rounddown(log(C6/4.96)*100,2) -> 34.74 | E6: =1.7495*D6*D6+158.59*D6+20971 -> 28591.831 | F6: =E6-20000 -> 8591.8315 | G6: =F6/$J$5 -> 16.109684 | H6: =G6-G5 -> 10.951136 | N6: 2 | O6: 에픽+유닠(중요) | P6: 10.63 | Q6: =rounddown(log(P6/4.96)*100,2) -> 33.1 | R6: 25999 | S6: 28137.099 | T6: =1.7253*power(Q6,2)+162.82*Q6+20864 -> 28143.598 | V6: 33.1 | W6: 25999 | X6: 25999
A7: 3 | B7: 유닠둘둘 | C7: 19.34 | D7: =rounddown(log(C7/4.96)*100,2) -> 59.09 | E7: =1.7495*D7*D7+158.59*D7+20971 -> 36450.686 | F7: =E7-20000 -> 16450.686 | G7: =F7/$J$5 -> 30.845037 | H7: =G7-G6 -> 14.735353 | K7: 1 | L7: 3.11 | N7: 3 | O7: 유닠둘둘 | P7: 18.78 | Q7: =rounddown(log(P7/4.96)*100,2) -> 57.82 | R7: 35746 | S7: 35989.519 | T7: =1.7253*power(Q7,2)+162.82*Q7+20864 -> 36046.193 | V7: 57.82 | W7: 35746 | X7: 35746
A8: 4 | B8: 18유닠둘둘 | C8: 32.65 | D8: =rounddown(log(C8/4.96)*100,2) -> 81.84 | E8: =1.7495*D8*D8+158.59*D8+20971 -> 45667.782 | F8: =E8-20000 -> 25667.782 | G8: =F8/$J$5 -> 48.12709 | H8: =G8-G7 -> 17.282053 | K8: 2 | L8: 10.61 | N8: 4 | O8: 18유닠둘둘 | P8: 31.84 | Q8: =rounddown(log(P8/4.96)*100,2) -> 80.74 | R8: 45401 | S8: 45180.455 | T8: =1.7253*power(Q8,2)+162.82*Q8+20864 -> 45257.227 | V8: 80.74 | W8: 45401 | X8: 45401
A9: 5 | B9: 레전둘둘 | C9: 51.74 | D9: =rounddown(log(C9/4.96)*100,2) -> 101.83 | E9: =1.7495*D9*D9+158.59*D9+20971 -> 55261.396 | F9: =E9-20000 -> 35261.396 | G9: =F9/$J$5 -> 66.115117 | H9: =G9-G8 -> 17.988026 | K9: 3 | L9: 14.79 | N9: 5 | O9: 레전둘둘 | P9: 50.46 | Q9: =rounddown(log(P9/4.96)*100,2) -> 100.74 | R9: 52536 | S9: 54702.241 | T9: =1.7253*power(Q9,2)+162.82*Q9+20864 -> 54775.776 | V9: 100.74 | W9: 52536 | X9: 52536
A10: 6 | B10: 노해방 초고스펙 | C10: 68.11 | D10: =rounddown(log(C10/4.96)*100,2) -> 113.77 | E10: =1.7495*D10*D10+158.59*D10+20971 -> 61658.635 | F10: =E10-20000 -> 41658.635 | G10: =F10/$J$5 -> 78.109941 | H10: =G10-G9 -> 11.994824 | I10: =H10-9.95 -> 2.044824 | K10: 4 | L10: 12.62 | N10: 6 | O10: 노해방 초고스펙 | P10: 66.28 | Q10: =rounddown(log(P10/4.96)*100,2) -> 112.59 | R10: 62876 | S10: 61004.199 | T10: =1.7253*power(Q10,2)+162.82*Q10+20864 -> 61066.683 | V10: 112.59 | W10: 62876 | X10: 62876
A11: 7 | B11: 해방 초고스펙 | C11: 85.47 | D11: =rounddown(log(C11/4.96)*100,2) -> 123.63 | E11: =1.7495*D11*D11+158.59*D11+20971 -> 67317.499 | F11: =E11-20000 -> 47317.499 | G11: =F11/$J$5 -> 88.720311 | H11: =G11-G10 -> 10.61037 | K11: 5 | L11: 13 | N11: 7 | O11: 해방 초고스펙 | P11: 84.08 | Q11: =rounddown(log(P11/4.96)*100,2) -> 122.92 | R11: 66686 | S11: 66898.649 | T11: =1.7253*power(Q11,2)+162.82*Q11+20864 -> 66945.955 | V11: 122.92 | W11: 66686 | X11: 66686
A12: 8 | B12: 5칠흑 엔드 | C12: 114.89 | D12: =rounddown(log(C12/4.96)*100,2) -> 136.48 | E12: =1.7495*D12*D12+158.59*D12+20971 -> 75202.933 | F12: =E12-20000 -> 55202.933 | G12: =F12/$J$5 -> 103.5055 | H12: =G12-G11 -> 14.785189 | K12: 6 | L12: 20.87 | N12: 8 | O12: 5칠흑 엔드 | P12: 115.57 | Q12: =rounddown(log(P12/4.96)*100,2) -> 136.73 | R12: 75456 | S12: 75362.076 | T12: =1.7253*power(Q12,2)+162.82*Q12+20864 -> 75381.022 | V12: 136.73 | W12: 75456 | X12: 75456
A13: 9 | B13: 엔드스펙 | C13: 145.61 | D13: =rounddown(log(C13/4.96)*100,2) -> 146.77 | E13: =1.7495*D13*D13+158.59*D13+20971 -> 81933.991 | F13: =E13-20000 -> 61933.991 | G13: =F13/$J$5 -> 116.12623 | H13: =G13-G12 -> 12.620734 | K13: 8 | L13: 50 | N13: 9 | O13: 엔드스펙 | P13: 140.71 | Q13: =rounddown(log(P13/4.96)*100,2) -> 145.28 | R13: 79972 | S13: 80936.389 | T13: =1.7253*power(Q13,2)+162.82*Q13+20864 -> 80933.152 | V13: 145.28 | W13: 79972 | X13: 79972
A14: 10 | B14: 그분들 | C14: 260.3 | D14: =rounddown(log(C14/4.96)*100,2) -> 171.99 | E14: =1.7495*D14*D14+158.59*D14+20971 -> 99998.084 | F14: =E14-20000 -> 79998.084 | G14: =F14/$J$5 -> 149.99641 | H14: =G14-G13 -> 33.870174 | I14: =sum(H14:H15) -> 33.873767 | K14: 9 | L14: 5.16 | N14: 10 | O14: 그분들 | P14: 270 | Q14: =rounddown(log(P14/4.96)*100,2) -> 173.58 | S14: 101211.52
C15: 270 | D15: =rounddown(log(C15/4.96)*100,2) -> 173.58 | E15: =1.7495*D15*D15+158.59*D15+20971 -> 101211.52 | F15: =E15-20000 -> 81211.516 | G15: 150 | H15: =G15-G14 -> 0.0035925095 | K15: 10 | L15: 10.95 | P15: 270 | Q15: =rounddown(log(P15/4.96)*100,2) -> 173.58
K16: 11 | L16: 14.74
K17: 12 | L17: 17.28
K18: 13 | L18: 17.99
K19: 14 | L19: 8.88
B23: =8.69+24.41+24.72+17.18 -> 75 | O23: =8.69+24.41+24.72+17.18 -> 75
